[2022-05-23 02:43:28,676] {taskinstance.py:1159} INFO - Dependencies all met for <TaskInstance: teste.teste manual__2022-05-23T02:43:28.118151+00:00 [queued]>
[2022-05-23 02:43:28,681] {taskinstance.py:1159} INFO - Dependencies all met for <TaskInstance: teste.teste manual__2022-05-23T02:43:28.118151+00:00 [queued]>
[2022-05-23 02:43:28,681] {taskinstance.py:1356} INFO - 
--------------------------------------------------------------------------------
[2022-05-23 02:43:28,681] {taskinstance.py:1357} INFO - Starting attempt 1 of 1
[2022-05-23 02:43:28,681] {taskinstance.py:1358} INFO - 
--------------------------------------------------------------------------------
[2022-05-23 02:43:28,692] {taskinstance.py:1377} INFO - Executing <Task(PostgresOperator): teste> on 2022-05-23 02:43:28.118151+00:00
[2022-05-23 02:43:28,695] {standard_task_runner.py:52} INFO - Started process 93 to run task
[2022-05-23 02:43:28,698] {standard_task_runner.py:79} INFO - Running: ['***', 'tasks', 'run', 'teste', 'teste', 'manual__2022-05-23T02:43:28.118151+00:00', '--job-id', '6', '--raw', '--subdir', 'DAGS_FOLDER/scripts/teste.py', '--cfg-path', '/tmp/tmpeuted82m', '--error-file', '/tmp/tmpsy_t8g0x']
[2022-05-23 02:43:28,698] {standard_task_runner.py:80} INFO - Job 6: Subtask teste
[2022-05-23 02:43:28,739] {task_command.py:369} INFO - Running <TaskInstance: teste.teste manual__2022-05-23T02:43:28.118151+00:00 [running]> on host f60453fe3eb1
[2022-05-23 02:43:28,782] {taskinstance.py:1889} ERROR - Task failed with exception
Traceback (most recent call last):
  File "/home/airflow/.local/lib/python3.7/site-packages/airflow/models/taskinstance.py", line 1451, in _run_raw_task
    self._execute_task_with_callbacks(context, test_mode)
  File "/home/airflow/.local/lib/python3.7/site-packages/airflow/models/taskinstance.py", line 1555, in _execute_task_with_callbacks
    task_orig = self.render_templates(context=context)
  File "/home/airflow/.local/lib/python3.7/site-packages/airflow/models/taskinstance.py", line 2202, in render_templates
    rendered_task = self.task.render_template_fields(context)
  File "/home/airflow/.local/lib/python3.7/site-packages/airflow/models/baseoperator.py", line 1179, in render_template_fields
    self._do_render_template_fields(self, self.template_fields, context, jinja_env, set())
  File "/home/airflow/.local/lib/python3.7/site-packages/airflow/utils/session.py", line 71, in wrapper
    return func(*args, session=session, **kwargs)
  File "/home/airflow/.local/lib/python3.7/site-packages/airflow/models/abstractoperator.py", line 348, in _do_render_template_fields
    seen_oids,
  File "/home/airflow/.local/lib/python3.7/site-packages/airflow/models/abstractoperator.py", line 385, in render_template
    template = jinja_env.get_template(value)
  File "/home/airflow/.local/lib/python3.7/site-packages/jinja2/environment.py", line 997, in get_template
    return self._load_template(name, globals)
  File "/home/airflow/.local/lib/python3.7/site-packages/jinja2/environment.py", line 958, in _load_template
    template = self.loader.load(self, name, self.make_globals(globals))
  File "/home/airflow/.local/lib/python3.7/site-packages/jinja2/loaders.py", line 125, in load
    source, filename, uptodate = self.get_source(environment, name)
  File "/home/airflow/.local/lib/python3.7/site-packages/jinja2/loaders.py", line 214, in get_source
    raise TemplateNotFound(template)
jinja2.exceptions.TemplateNotFound: /sql/teste.sql
[2022-05-23 02:43:28,791] {taskinstance.py:1400} INFO - Marking task as FAILED. dag_id=teste, task_id=teste, execution_date=20220523T024328, start_date=20220523T024328, end_date=20220523T024328
[2022-05-23 02:43:28,800] {standard_task_runner.py:97} ERROR - Failed to execute job 6 for task teste (/sql/teste.sql; 93)
[2022-05-23 02:43:28,829] {local_task_job.py:156} INFO - Task exited with return code 1
[2022-05-23 02:43:28,861] {local_task_job.py:273} INFO - 0 downstream tasks scheduled from follow-on schedule check
